2025-05-29 12:16:27 | ERROR    | logging:callHandlers:1736 - Traceback (most recent call last):
  File "/Users/kams/Documents/workspace/progo-app/Progo-BE/venv/lib/python3.13/site-packages/sqlalchemy/engine/base.py", line 145, in __init__
    self._dbapi_connection = engine.raw_connection()
                             ~~~~~~~~~~~~~~~~~~~~~^^
  File "/Users/kams/Documents/workspace/progo-app/Progo-BE/venv/lib/python3.13/site-packages/sqlalchemy/engine/base.py", line 3297, in raw_connection
    return self.pool.connect()
           ~~~~~~~~~~~~~~~~~^^
  File "/Users/kams/Documents/workspace/progo-app/Progo-BE/venv/lib/python3.13/site-packages/sqlalchemy/pool/base.py", line 449, in connect
    return _ConnectionFairy._checkout(self)
           ~~~~~~~~~~~~~~~~~~~~~~~~~~^^^^^^
  File "/Users/kams/Documents/workspace/progo-app/Progo-BE/venv/lib/python3.13/site-packages/sqlalchemy/pool/base.py", line 1264, in _checkout
    fairy = _ConnectionRecord.checkout(pool)
  File "/Users/kams/Documents/workspace/progo-app/Progo-BE/venv/lib/python3.13/site-packages/sqlalchemy/pool/base.py", line 713, in checkout
    rec = pool._do_get()
  File "/Users/kams/Documents/workspace/progo-app/Progo-BE/venv/lib/python3.13/site-packages/sqlalchemy/pool/impl.py", line 179, in _do_get
    with util.safe_reraise():
         ~~~~~~~~~~~~~~~~~^^
  File "/Users/kams/Documents/workspace/progo-app/Progo-BE/venv/lib/python3.13/site-packages/sqlalchemy/util/langhelpers.py", line 224, in __exit__
    raise exc_value.with_traceback(exc_tb)
  File "/Users/kams/Documents/workspace/progo-app/Progo-BE/venv/lib/python3.13/site-packages/sqlalchemy/pool/impl.py", line 177, in _do_get
    return self._create_connection()
           ~~~~~~~~~~~~~~~~~~~~~~~^^
  File "/Users/kams/Documents/workspace/progo-app/Progo-BE/venv/lib/python3.13/site-packages/sqlalchemy/pool/base.py", line 390, in _create_connection
    return _ConnectionRecord(self)
  File "/Users/kams/Documents/workspace/progo-app/Progo-BE/venv/lib/python3.13/site-packages/sqlalchemy/pool/base.py", line 675, in __init__
    self.__connect()
    ~~~~~~~~~~~~~~^^
  File "/Users/kams/Documents/workspace/progo-app/Progo-BE/venv/lib/python3.13/site-packages/sqlalchemy/pool/base.py", line 901, in __connect
    with util.safe_reraise():
         ~~~~~~~~~~~~~~~~~^^
  File "/Users/kams/Documents/workspace/progo-app/Progo-BE/venv/lib/python3.13/site-packages/sqlalchemy/util/langhelpers.py", line 224, in __exit__
    raise exc_value.with_traceback(exc_tb)
  File "/Users/kams/Documents/workspace/progo-app/Progo-BE/venv/lib/python3.13/site-packages/sqlalchemy/pool/base.py", line 897, in __connect
    self.dbapi_connection = connection = pool._invoke_creator(self)
                                         ~~~~~~~~~~~~~~~~~~~~^^^^^^
  File "/Users/kams/Documents/workspace/progo-app/Progo-BE/venv/lib/python3.13/site-packages/sqlalchemy/engine/create.py", line 646, in connect
    return dialect.connect(*cargs, **cparams)
           ~~~~~~~~~~~~~~~^^^^^^^^^^^^^^^^^^^
  File "/Users/kams/Documents/workspace/progo-app/Progo-BE/venv/lib/python3.13/site-packages/sqlalchemy/engine/default.py", line 625, in connect
    return self.loaded_dbapi.connect(*cargs, **cparams)  # type: ignore[no-any-return]  # NOQA: E501
           ~~~~~~~~~~~~~~~~~~~~~~~~~^^^^^^^^^^^^^^^^^^^
  File "/Users/kams/Documents/workspace/progo-app/Progo-BE/venv/lib/python3.13/site-packages/psycopg2/__init__.py", line 122, in connect
    conn = _connect(dsn, connection_factory=connection_factory, **kwasync)
psycopg2.OperationalError: connection to server at "localhost" (::1), port 5432 failed: FATAL:  role "postgres" does not exist


The above exception was the direct cause of the following exception:

Traceback (most recent call last):
  File "/Users/kams/Documents/workspace/progo-app/Progo-BE/venv/lib/python3.13/site-packages/starlette/routing.py", line 692, in lifespan
    async with self.lifespan_context(app) as maybe_state:
               ~~~~~~~~~~~~~~~~~~~~~^^^^^
  File "/usr/local/Cellar/python@3.13/3.13.3/Frameworks/Python.framework/Versions/3.13/lib/python3.13/contextlib.py", line 214, in __aenter__
    return await anext(self.gen)
           ^^^^^^^^^^^^^^^^^^^^^
  File "/Users/kams/Documents/workspace/progo-app/Progo-BE/venv/lib/python3.13/site-packages/fastapi/routing.py", line 133, in merged_lifespan
    async with original_context(app) as maybe_original_state:
               ~~~~~~~~~~~~~~~~^^^^^
  File "/usr/local/Cellar/python@3.13/3.13.3/Frameworks/Python.framework/Versions/3.13/lib/python3.13/contextlib.py", line 214, in __aenter__
    return await anext(self.gen)
           ^^^^^^^^^^^^^^^^^^^^^
  File "/Users/kams/Documents/workspace/progo-app/Progo-BE/venv/lib/python3.13/site-packages/fastapi/routing.py", line 133, in merged_lifespan
    async with original_context(app) as maybe_original_state:
               ~~~~~~~~~~~~~~~~^^^^^
  File "/usr/local/Cellar/python@3.13/3.13.3/Frameworks/Python.framework/Versions/3.13/lib/python3.13/contextlib.py", line 214, in __aenter__
    return await anext(self.gen)
           ^^^^^^^^^^^^^^^^^^^^^
  File "/Users/kams/Documents/workspace/progo-app/Progo-BE/venv/lib/python3.13/site-packages/fastapi/routing.py", line 133, in merged_lifespan
    async with original_context(app) as maybe_original_state:
               ~~~~~~~~~~~~~~~~^^^^^
  File "/usr/local/Cellar/python@3.13/3.13.3/Frameworks/Python.framework/Versions/3.13/lib/python3.13/contextlib.py", line 214, in __aenter__
    return await anext(self.gen)
           ^^^^^^^^^^^^^^^^^^^^^
  File "/Users/kams/Documents/workspace/progo-app/Progo-BE/app/main.py", line 34, in lifespan
    Base.metadata.create_all(bind=engine)
    ~~~~~~~~~~~~~~~~~~~~~~~~^^^^^^^^^^^^^
  File "/Users/kams/Documents/workspace/progo-app/Progo-BE/venv/lib/python3.13/site-packages/sqlalchemy/sql/schema.py", line 5924, in create_all
    bind._run_ddl_visitor(
    ~~~~~~~~~~~~~~~~~~~~~^
        ddl.SchemaGenerator, self, checkfirst=checkfirst, tables=tables
        ^^^^^^^^^^^^^^^^^^^^^^^^^^^^^^^^^^^^^^^^^^^^^^^^^^^^^^^^^^^^^^^
    )
    ^
  File "/Users/kams/Documents/workspace/progo-app/Progo-BE/venv/lib/python3.13/site-packages/sqlalchemy/engine/base.py", line 3247, in _run_ddl_visitor
    with self.begin() as conn:
         ~~~~~~~~~~^^
  File "/usr/local/Cellar/python@3.13/3.13.3/Frameworks/Python.framework/Versions/3.13/lib/python3.13/contextlib.py", line 141, in __enter__
    return next(self.gen)
  File "/Users/kams/Documents/workspace/progo-app/Progo-BE/venv/lib/python3.13/site-packages/sqlalchemy/engine/base.py", line 3237, in begin
    with self.connect() as conn:
         ~~~~~~~~~~~~^^
  File "/Users/kams/Documents/workspace/progo-app/Progo-BE/venv/lib/python3.13/site-packages/sqlalchemy/engine/base.py", line 3273, in connect
    return self._connection_cls(self)
           ~~~~~~~~~~~~~~~~~~~~^^^^^^
  File "/Users/kams/Documents/workspace/progo-app/Progo-BE/venv/lib/python3.13/site-packages/sqlalchemy/engine/base.py", line 147, in __init__
    Connection._handle_dbapi_exception_noconnection(
    ~~~~~~~~~~~~~~~~~~~~~~~~~~~~~~~~~~~~~~~~~~~~~~~^
        err, dialect, engine
        ^^^^^^^^^^^^^^^^^^^^
    )
    ^
  File "/Users/kams/Documents/workspace/progo-app/Progo-BE/venv/lib/python3.13/site-packages/sqlalchemy/engine/base.py", line 2436, in _handle_dbapi_exception_noconnection
    raise sqlalchemy_exception.with_traceback(exc_info[2]) from e
  File "/Users/kams/Documents/workspace/progo-app/Progo-BE/venv/lib/python3.13/site-packages/sqlalchemy/engine/base.py", line 145, in __init__
    self._dbapi_connection = engine.raw_connection()
                             ~~~~~~~~~~~~~~~~~~~~~^^
  File "/Users/kams/Documents/workspace/progo-app/Progo-BE/venv/lib/python3.13/site-packages/sqlalchemy/engine/base.py", line 3297, in raw_connection
    return self.pool.connect()
           ~~~~~~~~~~~~~~~~~^^
  File "/Users/kams/Documents/workspace/progo-app/Progo-BE/venv/lib/python3.13/site-packages/sqlalchemy/pool/base.py", line 449, in connect
    return _ConnectionFairy._checkout(self)
           ~~~~~~~~~~~~~~~~~~~~~~~~~~^^^^^^
  File "/Users/kams/Documents/workspace/progo-app/Progo-BE/venv/lib/python3.13/site-packages/sqlalchemy/pool/base.py", line 1264, in _checkout
    fairy = _ConnectionRecord.checkout(pool)
  File "/Users/kams/Documents/workspace/progo-app/Progo-BE/venv/lib/python3.13/site-packages/sqlalchemy/pool/base.py", line 713, in checkout
    rec = pool._do_get()
  File "/Users/kams/Documents/workspace/progo-app/Progo-BE/venv/lib/python3.13/site-packages/sqlalchemy/pool/impl.py", line 179, in _do_get
    with util.safe_reraise():
         ~~~~~~~~~~~~~~~~~^^
  File "/Users/kams/Documents/workspace/progo-app/Progo-BE/venv/lib/python3.13/site-packages/sqlalchemy/util/langhelpers.py", line 224, in __exit__
    raise exc_value.with_traceback(exc_tb)
  File "/Users/kams/Documents/workspace/progo-app/Progo-BE/venv/lib/python3.13/site-packages/sqlalchemy/pool/impl.py", line 177, in _do_get
    return self._create_connection()
           ~~~~~~~~~~~~~~~~~~~~~~~^^
  File "/Users/kams/Documents/workspace/progo-app/Progo-BE/venv/lib/python3.13/site-packages/sqlalchemy/pool/base.py", line 390, in _create_connection
    return _ConnectionRecord(self)
  File "/Users/kams/Documents/workspace/progo-app/Progo-BE/venv/lib/python3.13/site-packages/sqlalchemy/pool/base.py", line 675, in __init__
    self.__connect()
    ~~~~~~~~~~~~~~^^
  File "/Users/kams/Documents/workspace/progo-app/Progo-BE/venv/lib/python3.13/site-packages/sqlalchemy/pool/base.py", line 901, in __connect
    with util.safe_reraise():
         ~~~~~~~~~~~~~~~~~^^
  File "/Users/kams/Documents/workspace/progo-app/Progo-BE/venv/lib/python3.13/site-packages/sqlalchemy/util/langhelpers.py", line 224, in __exit__
    raise exc_value.with_traceback(exc_tb)
  File "/Users/kams/Documents/workspace/progo-app/Progo-BE/venv/lib/python3.13/site-packages/sqlalchemy/pool/base.py", line 897, in __connect
    self.dbapi_connection = connection = pool._invoke_creator(self)
                                         ~~~~~~~~~~~~~~~~~~~~^^^^^^
  File "/Users/kams/Documents/workspace/progo-app/Progo-BE/venv/lib/python3.13/site-packages/sqlalchemy/engine/create.py", line 646, in connect
    return dialect.connect(*cargs, **cparams)
           ~~~~~~~~~~~~~~~^^^^^^^^^^^^^^^^^^^
  File "/Users/kams/Documents/workspace/progo-app/Progo-BE/venv/lib/python3.13/site-packages/sqlalchemy/engine/default.py", line 625, in connect
    return self.loaded_dbapi.connect(*cargs, **cparams)  # type: ignore[no-any-return]  # NOQA: E501
           ~~~~~~~~~~~~~~~~~~~~~~~~~^^^^^^^^^^^^^^^^^^^
  File "/Users/kams/Documents/workspace/progo-app/Progo-BE/venv/lib/python3.13/site-packages/psycopg2/__init__.py", line 122, in connect
    conn = _connect(dsn, connection_factory=connection_factory, **kwasync)
sqlalchemy.exc.OperationalError: (psycopg2.OperationalError) connection to server at "localhost" (::1), port 5432 failed: FATAL:  role "postgres" does not exist

(Background on this error at: https://sqlalche.me/e/20/e3q8)

2025-05-29 12:16:27 | ERROR    | logging:callHandlers:1736 - Application startup failed. Exiting.
2025-05-29 12:17:05 | ERROR    | logging:callHandlers:1736 - Traceback (most recent call last):
  File "/Users/kams/Documents/workspace/progo-app/Progo-BE/venv/lib/python3.13/site-packages/sqlalchemy/engine/base.py", line 145, in __init__
    self._dbapi_connection = engine.raw_connection()
                             ~~~~~~~~~~~~~~~~~~~~~^^
  File "/Users/kams/Documents/workspace/progo-app/Progo-BE/venv/lib/python3.13/site-packages/sqlalchemy/engine/base.py", line 3297, in raw_connection
    return self.pool.connect()
           ~~~~~~~~~~~~~~~~~^^
  File "/Users/kams/Documents/workspace/progo-app/Progo-BE/venv/lib/python3.13/site-packages/sqlalchemy/pool/base.py", line 449, in connect
    return _ConnectionFairy._checkout(self)
           ~~~~~~~~~~~~~~~~~~~~~~~~~~^^^^^^
  File "/Users/kams/Documents/workspace/progo-app/Progo-BE/venv/lib/python3.13/site-packages/sqlalchemy/pool/base.py", line 1264, in _checkout
    fairy = _ConnectionRecord.checkout(pool)
  File "/Users/kams/Documents/workspace/progo-app/Progo-BE/venv/lib/python3.13/site-packages/sqlalchemy/pool/base.py", line 713, in checkout
    rec = pool._do_get()
  File "/Users/kams/Documents/workspace/progo-app/Progo-BE/venv/lib/python3.13/site-packages/sqlalchemy/pool/impl.py", line 179, in _do_get
    with util.safe_reraise():
         ~~~~~~~~~~~~~~~~~^^
  File "/Users/kams/Documents/workspace/progo-app/Progo-BE/venv/lib/python3.13/site-packages/sqlalchemy/util/langhelpers.py", line 224, in __exit__
    raise exc_value.with_traceback(exc_tb)
  File "/Users/kams/Documents/workspace/progo-app/Progo-BE/venv/lib/python3.13/site-packages/sqlalchemy/pool/impl.py", line 177, in _do_get
    return self._create_connection()
           ~~~~~~~~~~~~~~~~~~~~~~~^^
  File "/Users/kams/Documents/workspace/progo-app/Progo-BE/venv/lib/python3.13/site-packages/sqlalchemy/pool/base.py", line 390, in _create_connection
    return _ConnectionRecord(self)
  File "/Users/kams/Documents/workspace/progo-app/Progo-BE/venv/lib/python3.13/site-packages/sqlalchemy/pool/base.py", line 675, in __init__
    self.__connect()
    ~~~~~~~~~~~~~~^^
  File "/Users/kams/Documents/workspace/progo-app/Progo-BE/venv/lib/python3.13/site-packages/sqlalchemy/pool/base.py", line 901, in __connect
    with util.safe_reraise():
         ~~~~~~~~~~~~~~~~~^^
  File "/Users/kams/Documents/workspace/progo-app/Progo-BE/venv/lib/python3.13/site-packages/sqlalchemy/util/langhelpers.py", line 224, in __exit__
    raise exc_value.with_traceback(exc_tb)
  File "/Users/kams/Documents/workspace/progo-app/Progo-BE/venv/lib/python3.13/site-packages/sqlalchemy/pool/base.py", line 897, in __connect
    self.dbapi_connection = connection = pool._invoke_creator(self)
                                         ~~~~~~~~~~~~~~~~~~~~^^^^^^
  File "/Users/kams/Documents/workspace/progo-app/Progo-BE/venv/lib/python3.13/site-packages/sqlalchemy/engine/create.py", line 646, in connect
    return dialect.connect(*cargs, **cparams)
           ~~~~~~~~~~~~~~~^^^^^^^^^^^^^^^^^^^
  File "/Users/kams/Documents/workspace/progo-app/Progo-BE/venv/lib/python3.13/site-packages/sqlalchemy/engine/default.py", line 625, in connect
    return self.loaded_dbapi.connect(*cargs, **cparams)  # type: ignore[no-any-return]  # NOQA: E501
           ~~~~~~~~~~~~~~~~~~~~~~~~~^^^^^^^^^^^^^^^^^^^
  File "/Users/kams/Documents/workspace/progo-app/Progo-BE/venv/lib/python3.13/site-packages/psycopg2/__init__.py", line 122, in connect
    conn = _connect(dsn, connection_factory=connection_factory, **kwasync)
psycopg2.OperationalError: connection to server at "localhost" (::1), port 5432 failed: FATAL:  role "postgres" does not exist


The above exception was the direct cause of the following exception:

Traceback (most recent call last):
  File "/Users/kams/Documents/workspace/progo-app/Progo-BE/venv/lib/python3.13/site-packages/starlette/routing.py", line 692, in lifespan
    async with self.lifespan_context(app) as maybe_state:
               ~~~~~~~~~~~~~~~~~~~~~^^^^^
  File "/usr/local/Cellar/python@3.13/3.13.3/Frameworks/Python.framework/Versions/3.13/lib/python3.13/contextlib.py", line 214, in __aenter__
    return await anext(self.gen)
           ^^^^^^^^^^^^^^^^^^^^^
  File "/Users/kams/Documents/workspace/progo-app/Progo-BE/venv/lib/python3.13/site-packages/fastapi/routing.py", line 133, in merged_lifespan
    async with original_context(app) as maybe_original_state:
               ~~~~~~~~~~~~~~~~^^^^^
  File "/usr/local/Cellar/python@3.13/3.13.3/Frameworks/Python.framework/Versions/3.13/lib/python3.13/contextlib.py", line 214, in __aenter__
    return await anext(self.gen)
           ^^^^^^^^^^^^^^^^^^^^^
  File "/Users/kams/Documents/workspace/progo-app/Progo-BE/venv/lib/python3.13/site-packages/fastapi/routing.py", line 133, in merged_lifespan
    async with original_context(app) as maybe_original_state:
               ~~~~~~~~~~~~~~~~^^^^^
  File "/usr/local/Cellar/python@3.13/3.13.3/Frameworks/Python.framework/Versions/3.13/lib/python3.13/contextlib.py", line 214, in __aenter__
    return await anext(self.gen)
           ^^^^^^^^^^^^^^^^^^^^^
  File "/Users/kams/Documents/workspace/progo-app/Progo-BE/venv/lib/python3.13/site-packages/fastapi/routing.py", line 133, in merged_lifespan
    async with original_context(app) as maybe_original_state:
               ~~~~~~~~~~~~~~~~^^^^^
  File "/usr/local/Cellar/python@3.13/3.13.3/Frameworks/Python.framework/Versions/3.13/lib/python3.13/contextlib.py", line 214, in __aenter__
    return await anext(self.gen)
           ^^^^^^^^^^^^^^^^^^^^^
  File "/Users/kams/Documents/workspace/progo-app/Progo-BE/app/main.py", line 34, in lifespan
    Base.metadata.create_all(bind=engine)
    ~~~~~~~~~~~~~~~~~~~~~~~~^^^^^^^^^^^^^
  File "/Users/kams/Documents/workspace/progo-app/Progo-BE/venv/lib/python3.13/site-packages/sqlalchemy/sql/schema.py", line 5924, in create_all
    bind._run_ddl_visitor(
    ~~~~~~~~~~~~~~~~~~~~~^
        ddl.SchemaGenerator, self, checkfirst=checkfirst, tables=tables
        ^^^^^^^^^^^^^^^^^^^^^^^^^^^^^^^^^^^^^^^^^^^^^^^^^^^^^^^^^^^^^^^
    )
    ^
  File "/Users/kams/Documents/workspace/progo-app/Progo-BE/venv/lib/python3.13/site-packages/sqlalchemy/engine/base.py", line 3247, in _run_ddl_visitor
    with self.begin() as conn:
         ~~~~~~~~~~^^
  File "/usr/local/Cellar/python@3.13/3.13.3/Frameworks/Python.framework/Versions/3.13/lib/python3.13/contextlib.py", line 141, in __enter__
    return next(self.gen)
  File "/Users/kams/Documents/workspace/progo-app/Progo-BE/venv/lib/python3.13/site-packages/sqlalchemy/engine/base.py", line 3237, in begin
    with self.connect() as conn:
         ~~~~~~~~~~~~^^
  File "/Users/kams/Documents/workspace/progo-app/Progo-BE/venv/lib/python3.13/site-packages/sqlalchemy/engine/base.py", line 3273, in connect
    return self._connection_cls(self)
           ~~~~~~~~~~~~~~~~~~~~^^^^^^
  File "/Users/kams/Documents/workspace/progo-app/Progo-BE/venv/lib/python3.13/site-packages/sqlalchemy/engine/base.py", line 147, in __init__
    Connection._handle_dbapi_exception_noconnection(
    ~~~~~~~~~~~~~~~~~~~~~~~~~~~~~~~~~~~~~~~~~~~~~~~^
        err, dialect, engine
        ^^^^^^^^^^^^^^^^^^^^
    )
    ^
  File "/Users/kams/Documents/workspace/progo-app/Progo-BE/venv/lib/python3.13/site-packages/sqlalchemy/engine/base.py", line 2436, in _handle_dbapi_exception_noconnection
    raise sqlalchemy_exception.with_traceback(exc_info[2]) from e
  File "/Users/kams/Documents/workspace/progo-app/Progo-BE/venv/lib/python3.13/site-packages/sqlalchemy/engine/base.py", line 145, in __init__
    self._dbapi_connection = engine.raw_connection()
                             ~~~~~~~~~~~~~~~~~~~~~^^
  File "/Users/kams/Documents/workspace/progo-app/Progo-BE/venv/lib/python3.13/site-packages/sqlalchemy/engine/base.py", line 3297, in raw_connection
    return self.pool.connect()
           ~~~~~~~~~~~~~~~~~^^
  File "/Users/kams/Documents/workspace/progo-app/Progo-BE/venv/lib/python3.13/site-packages/sqlalchemy/pool/base.py", line 449, in connect
    return _ConnectionFairy._checkout(self)
           ~~~~~~~~~~~~~~~~~~~~~~~~~~^^^^^^
  File "/Users/kams/Documents/workspace/progo-app/Progo-BE/venv/lib/python3.13/site-packages/sqlalchemy/pool/base.py", line 1264, in _checkout
    fairy = _ConnectionRecord.checkout(pool)
  File "/Users/kams/Documents/workspace/progo-app/Progo-BE/venv/lib/python3.13/site-packages/sqlalchemy/pool/base.py", line 713, in checkout
    rec = pool._do_get()
  File "/Users/kams/Documents/workspace/progo-app/Progo-BE/venv/lib/python3.13/site-packages/sqlalchemy/pool/impl.py", line 179, in _do_get
    with util.safe_reraise():
         ~~~~~~~~~~~~~~~~~^^
  File "/Users/kams/Documents/workspace/progo-app/Progo-BE/venv/lib/python3.13/site-packages/sqlalchemy/util/langhelpers.py", line 224, in __exit__
    raise exc_value.with_traceback(exc_tb)
  File "/Users/kams/Documents/workspace/progo-app/Progo-BE/venv/lib/python3.13/site-packages/sqlalchemy/pool/impl.py", line 177, in _do_get
    return self._create_connection()
           ~~~~~~~~~~~~~~~~~~~~~~~^^
  File "/Users/kams/Documents/workspace/progo-app/Progo-BE/venv/lib/python3.13/site-packages/sqlalchemy/pool/base.py", line 390, in _create_connection
    return _ConnectionRecord(self)
  File "/Users/kams/Documents/workspace/progo-app/Progo-BE/venv/lib/python3.13/site-packages/sqlalchemy/pool/base.py", line 675, in __init__
    self.__connect()
    ~~~~~~~~~~~~~~^^
  File "/Users/kams/Documents/workspace/progo-app/Progo-BE/venv/lib/python3.13/site-packages/sqlalchemy/pool/base.py", line 901, in __connect
    with util.safe_reraise():
         ~~~~~~~~~~~~~~~~~^^
  File "/Users/kams/Documents/workspace/progo-app/Progo-BE/venv/lib/python3.13/site-packages/sqlalchemy/util/langhelpers.py", line 224, in __exit__
    raise exc_value.with_traceback(exc_tb)
  File "/Users/kams/Documents/workspace/progo-app/Progo-BE/venv/lib/python3.13/site-packages/sqlalchemy/pool/base.py", line 897, in __connect
    self.dbapi_connection = connection = pool._invoke_creator(self)
                                         ~~~~~~~~~~~~~~~~~~~~^^^^^^
  File "/Users/kams/Documents/workspace/progo-app/Progo-BE/venv/lib/python3.13/site-packages/sqlalchemy/engine/create.py", line 646, in connect
    return dialect.connect(*cargs, **cparams)
           ~~~~~~~~~~~~~~~^^^^^^^^^^^^^^^^^^^
  File "/Users/kams/Documents/workspace/progo-app/Progo-BE/venv/lib/python3.13/site-packages/sqlalchemy/engine/default.py", line 625, in connect
    return self.loaded_dbapi.connect(*cargs, **cparams)  # type: ignore[no-any-return]  # NOQA: E501
           ~~~~~~~~~~~~~~~~~~~~~~~~~^^^^^^^^^^^^^^^^^^^
  File "/Users/kams/Documents/workspace/progo-app/Progo-BE/venv/lib/python3.13/site-packages/psycopg2/__init__.py", line 122, in connect
    conn = _connect(dsn, connection_factory=connection_factory, **kwasync)
sqlalchemy.exc.OperationalError: (psycopg2.OperationalError) connection to server at "localhost" (::1), port 5432 failed: FATAL:  role "postgres" does not exist

(Background on this error at: https://sqlalche.me/e/20/e3q8)

2025-05-29 12:17:05 | ERROR    | logging:callHandlers:1736 - Application startup failed. Exiting.
2025-05-29 12:17:17 | ERROR    | logging:callHandlers:1736 - Traceback (most recent call last):
  File "/Users/kams/Documents/workspace/progo-app/Progo-BE/venv/lib/python3.13/site-packages/sqlalchemy/engine/base.py", line 145, in __init__
    self._dbapi_connection = engine.raw_connection()
                             ~~~~~~~~~~~~~~~~~~~~~^^
  File "/Users/kams/Documents/workspace/progo-app/Progo-BE/venv/lib/python3.13/site-packages/sqlalchemy/engine/base.py", line 3297, in raw_connection
    return self.pool.connect()
           ~~~~~~~~~~~~~~~~~^^
  File "/Users/kams/Documents/workspace/progo-app/Progo-BE/venv/lib/python3.13/site-packages/sqlalchemy/pool/base.py", line 449, in connect
    return _ConnectionFairy._checkout(self)
           ~~~~~~~~~~~~~~~~~~~~~~~~~~^^^^^^
  File "/Users/kams/Documents/workspace/progo-app/Progo-BE/venv/lib/python3.13/site-packages/sqlalchemy/pool/base.py", line 1264, in _checkout
    fairy = _ConnectionRecord.checkout(pool)
  File "/Users/kams/Documents/workspace/progo-app/Progo-BE/venv/lib/python3.13/site-packages/sqlalchemy/pool/base.py", line 713, in checkout
    rec = pool._do_get()
  File "/Users/kams/Documents/workspace/progo-app/Progo-BE/venv/lib/python3.13/site-packages/sqlalchemy/pool/impl.py", line 179, in _do_get
    with util.safe_reraise():
         ~~~~~~~~~~~~~~~~~^^
  File "/Users/kams/Documents/workspace/progo-app/Progo-BE/venv/lib/python3.13/site-packages/sqlalchemy/util/langhelpers.py", line 224, in __exit__
    raise exc_value.with_traceback(exc_tb)
  File "/Users/kams/Documents/workspace/progo-app/Progo-BE/venv/lib/python3.13/site-packages/sqlalchemy/pool/impl.py", line 177, in _do_get
    return self._create_connection()
           ~~~~~~~~~~~~~~~~~~~~~~~^^
  File "/Users/kams/Documents/workspace/progo-app/Progo-BE/venv/lib/python3.13/site-packages/sqlalchemy/pool/base.py", line 390, in _create_connection
    return _ConnectionRecord(self)
  File "/Users/kams/Documents/workspace/progo-app/Progo-BE/venv/lib/python3.13/site-packages/sqlalchemy/pool/base.py", line 675, in __init__
    self.__connect()
    ~~~~~~~~~~~~~~^^
  File "/Users/kams/Documents/workspace/progo-app/Progo-BE/venv/lib/python3.13/site-packages/sqlalchemy/pool/base.py", line 901, in __connect
    with util.safe_reraise():
         ~~~~~~~~~~~~~~~~~^^
  File "/Users/kams/Documents/workspace/progo-app/Progo-BE/venv/lib/python3.13/site-packages/sqlalchemy/util/langhelpers.py", line 224, in __exit__
    raise exc_value.with_traceback(exc_tb)
  File "/Users/kams/Documents/workspace/progo-app/Progo-BE/venv/lib/python3.13/site-packages/sqlalchemy/pool/base.py", line 897, in __connect
    self.dbapi_connection = connection = pool._invoke_creator(self)
                                         ~~~~~~~~~~~~~~~~~~~~^^^^^^
  File "/Users/kams/Documents/workspace/progo-app/Progo-BE/venv/lib/python3.13/site-packages/sqlalchemy/engine/create.py", line 646, in connect
    return dialect.connect(*cargs, **cparams)
           ~~~~~~~~~~~~~~~^^^^^^^^^^^^^^^^^^^
  File "/Users/kams/Documents/workspace/progo-app/Progo-BE/venv/lib/python3.13/site-packages/sqlalchemy/engine/default.py", line 625, in connect
    return self.loaded_dbapi.connect(*cargs, **cparams)  # type: ignore[no-any-return]  # NOQA: E501
           ~~~~~~~~~~~~~~~~~~~~~~~~~^^^^^^^^^^^^^^^^^^^
  File "/Users/kams/Documents/workspace/progo-app/Progo-BE/venv/lib/python3.13/site-packages/psycopg2/__init__.py", line 122, in connect
    conn = _connect(dsn, connection_factory=connection_factory, **kwasync)
psycopg2.OperationalError: connection to server at "localhost" (::1), port 5432 failed: FATAL:  role "postgres" does not exist


The above exception was the direct cause of the following exception:

Traceback (most recent call last):
  File "/Users/kams/Documents/workspace/progo-app/Progo-BE/venv/lib/python3.13/site-packages/starlette/routing.py", line 692, in lifespan
    async with self.lifespan_context(app) as maybe_state:
               ~~~~~~~~~~~~~~~~~~~~~^^^^^
  File "/usr/local/Cellar/python@3.13/3.13.3/Frameworks/Python.framework/Versions/3.13/lib/python3.13/contextlib.py", line 214, in __aenter__
    return await anext(self.gen)
           ^^^^^^^^^^^^^^^^^^^^^
  File "/Users/kams/Documents/workspace/progo-app/Progo-BE/venv/lib/python3.13/site-packages/fastapi/routing.py", line 133, in merged_lifespan
    async with original_context(app) as maybe_original_state:
               ~~~~~~~~~~~~~~~~^^^^^
  File "/usr/local/Cellar/python@3.13/3.13.3/Frameworks/Python.framework/Versions/3.13/lib/python3.13/contextlib.py", line 214, in __aenter__
    return await anext(self.gen)
           ^^^^^^^^^^^^^^^^^^^^^
  File "/Users/kams/Documents/workspace/progo-app/Progo-BE/venv/lib/python3.13/site-packages/fastapi/routing.py", line 133, in merged_lifespan
    async with original_context(app) as maybe_original_state:
               ~~~~~~~~~~~~~~~~^^^^^
  File "/usr/local/Cellar/python@3.13/3.13.3/Frameworks/Python.framework/Versions/3.13/lib/python3.13/contextlib.py", line 214, in __aenter__
    return await anext(self.gen)
           ^^^^^^^^^^^^^^^^^^^^^
  File "/Users/kams/Documents/workspace/progo-app/Progo-BE/venv/lib/python3.13/site-packages/fastapi/routing.py", line 133, in merged_lifespan
    async with original_context(app) as maybe_original_state:
               ~~~~~~~~~~~~~~~~^^^^^
  File "/usr/local/Cellar/python@3.13/3.13.3/Frameworks/Python.framework/Versions/3.13/lib/python3.13/contextlib.py", line 214, in __aenter__
    return await anext(self.gen)
           ^^^^^^^^^^^^^^^^^^^^^
  File "/Users/kams/Documents/workspace/progo-app/Progo-BE/app/main.py", line 34, in lifespan
    Base.metadata.create_all(bind=engine)
    ~~~~~~~~~~~~~~~~~~~~~~~~^^^^^^^^^^^^^
  File "/Users/kams/Documents/workspace/progo-app/Progo-BE/venv/lib/python3.13/site-packages/sqlalchemy/sql/schema.py", line 5924, in create_all
    bind._run_ddl_visitor(
    ~~~~~~~~~~~~~~~~~~~~~^
        ddl.SchemaGenerator, self, checkfirst=checkfirst, tables=tables
        ^^^^^^^^^^^^^^^^^^^^^^^^^^^^^^^^^^^^^^^^^^^^^^^^^^^^^^^^^^^^^^^
    )
    ^
  File "/Users/kams/Documents/workspace/progo-app/Progo-BE/venv/lib/python3.13/site-packages/sqlalchemy/engine/base.py", line 3247, in _run_ddl_visitor
    with self.begin() as conn:
         ~~~~~~~~~~^^
  File "/usr/local/Cellar/python@3.13/3.13.3/Frameworks/Python.framework/Versions/3.13/lib/python3.13/contextlib.py", line 141, in __enter__
    return next(self.gen)
  File "/Users/kams/Documents/workspace/progo-app/Progo-BE/venv/lib/python3.13/site-packages/sqlalchemy/engine/base.py", line 3237, in begin
    with self.connect() as conn:
         ~~~~~~~~~~~~^^
  File "/Users/kams/Documents/workspace/progo-app/Progo-BE/venv/lib/python3.13/site-packages/sqlalchemy/engine/base.py", line 3273, in connect
    return self._connection_cls(self)
           ~~~~~~~~~~~~~~~~~~~~^^^^^^
  File "/Users/kams/Documents/workspace/progo-app/Progo-BE/venv/lib/python3.13/site-packages/sqlalchemy/engine/base.py", line 147, in __init__
    Connection._handle_dbapi_exception_noconnection(
    ~~~~~~~~~~~~~~~~~~~~~~~~~~~~~~~~~~~~~~~~~~~~~~~^
        err, dialect, engine
        ^^^^^^^^^^^^^^^^^^^^
    )
    ^
  File "/Users/kams/Documents/workspace/progo-app/Progo-BE/venv/lib/python3.13/site-packages/sqlalchemy/engine/base.py", line 2436, in _handle_dbapi_exception_noconnection
    raise sqlalchemy_exception.with_traceback(exc_info[2]) from e
  File "/Users/kams/Documents/workspace/progo-app/Progo-BE/venv/lib/python3.13/site-packages/sqlalchemy/engine/base.py", line 145, in __init__
    self._dbapi_connection = engine.raw_connection()
                             ~~~~~~~~~~~~~~~~~~~~~^^
  File "/Users/kams/Documents/workspace/progo-app/Progo-BE/venv/lib/python3.13/site-packages/sqlalchemy/engine/base.py", line 3297, in raw_connection
    return self.pool.connect()
           ~~~~~~~~~~~~~~~~~^^
  File "/Users/kams/Documents/workspace/progo-app/Progo-BE/venv/lib/python3.13/site-packages/sqlalchemy/pool/base.py", line 449, in connect
    return _ConnectionFairy._checkout(self)
           ~~~~~~~~~~~~~~~~~~~~~~~~~~^^^^^^
  File "/Users/kams/Documents/workspace/progo-app/Progo-BE/venv/lib/python3.13/site-packages/sqlalchemy/pool/base.py", line 1264, in _checkout
    fairy = _ConnectionRecord.checkout(pool)
  File "/Users/kams/Documents/workspace/progo-app/Progo-BE/venv/lib/python3.13/site-packages/sqlalchemy/pool/base.py", line 713, in checkout
    rec = pool._do_get()
  File "/Users/kams/Documents/workspace/progo-app/Progo-BE/venv/lib/python3.13/site-packages/sqlalchemy/pool/impl.py", line 179, in _do_get
    with util.safe_reraise():
         ~~~~~~~~~~~~~~~~~^^
  File "/Users/kams/Documents/workspace/progo-app/Progo-BE/venv/lib/python3.13/site-packages/sqlalchemy/util/langhelpers.py", line 224, in __exit__
    raise exc_value.with_traceback(exc_tb)
  File "/Users/kams/Documents/workspace/progo-app/Progo-BE/venv/lib/python3.13/site-packages/sqlalchemy/pool/impl.py", line 177, in _do_get
    return self._create_connection()
           ~~~~~~~~~~~~~~~~~~~~~~~^^
  File "/Users/kams/Documents/workspace/progo-app/Progo-BE/venv/lib/python3.13/site-packages/sqlalchemy/pool/base.py", line 390, in _create_connection
    return _ConnectionRecord(self)
  File "/Users/kams/Documents/workspace/progo-app/Progo-BE/venv/lib/python3.13/site-packages/sqlalchemy/pool/base.py", line 675, in __init__
    self.__connect()
    ~~~~~~~~~~~~~~^^
  File "/Users/kams/Documents/workspace/progo-app/Progo-BE/venv/lib/python3.13/site-packages/sqlalchemy/pool/base.py", line 901, in __connect
    with util.safe_reraise():
         ~~~~~~~~~~~~~~~~~^^
  File "/Users/kams/Documents/workspace/progo-app/Progo-BE/venv/lib/python3.13/site-packages/sqlalchemy/util/langhelpers.py", line 224, in __exit__
    raise exc_value.with_traceback(exc_tb)
  File "/Users/kams/Documents/workspace/progo-app/Progo-BE/venv/lib/python3.13/site-packages/sqlalchemy/pool/base.py", line 897, in __connect
    self.dbapi_connection = connection = pool._invoke_creator(self)
                                         ~~~~~~~~~~~~~~~~~~~~^^^^^^
  File "/Users/kams/Documents/workspace/progo-app/Progo-BE/venv/lib/python3.13/site-packages/sqlalchemy/engine/create.py", line 646, in connect
    return dialect.connect(*cargs, **cparams)
           ~~~~~~~~~~~~~~~^^^^^^^^^^^^^^^^^^^
  File "/Users/kams/Documents/workspace/progo-app/Progo-BE/venv/lib/python3.13/site-packages/sqlalchemy/engine/default.py", line 625, in connect
    return self.loaded_dbapi.connect(*cargs, **cparams)  # type: ignore[no-any-return]  # NOQA: E501
           ~~~~~~~~~~~~~~~~~~~~~~~~~^^^^^^^^^^^^^^^^^^^
  File "/Users/kams/Documents/workspace/progo-app/Progo-BE/venv/lib/python3.13/site-packages/psycopg2/__init__.py", line 122, in connect
    conn = _connect(dsn, connection_factory=connection_factory, **kwasync)
sqlalchemy.exc.OperationalError: (psycopg2.OperationalError) connection to server at "localhost" (::1), port 5432 failed: FATAL:  role "postgres" does not exist

(Background on this error at: https://sqlalche.me/e/20/e3q8)

2025-05-29 12:17:17 | ERROR    | logging:callHandlers:1736 - Application startup failed. Exiting.
2025-05-29 12:27:17 | ERROR    | logging:callHandlers:1736 - Error querying sensor data: 'AsyncSession' object has no attribute 'query'
2025-05-29 12:27:17 | ERROR    | logging:callHandlers:1736 - Error creating exercise session: 3 validation errors for ExerciseSessionResponse
id
  Input should be a valid integer [type=int_type, input_value=None, input_type=NoneType]
    For further information visit https://errors.pydantic.dev/2.11/v/int_type
start_time
  Input should be a valid datetime [type=datetime_type, input_value=None, input_type=NoneType]
    For further information visit https://errors.pydantic.dev/2.11/v/datetime_type
is_labeled
  Input should be a valid boolean [type=bool_type, input_value=None, input_type=NoneType]
    For further information visit https://errors.pydantic.dev/2.11/v/bool_type
2025-05-29 12:27:18 | ERROR    | logging:callHandlers:1736 - Error getting exercise sessions: 'AsyncSession' object has no attribute 'query'
2025-05-29 12:27:18 | ERROR    | logging:callHandlers:1736 - Error getting ML status: 'AsyncSession' object has no attribute 'query'
2025-05-29 12:27:19 | ERROR    | logging:callHandlers:1736 - Error getting models: 'AsyncSession' object has no attribute 'query'
2025-05-29 12:33:41 | ERROR    | logging:callHandlers:1736 - No active model found with name: default_classifier
2025-05-29 12:34:47 | ERROR    | logging:callHandlers:1736 - No active model found with name: default_classifier
2025-05-29 12:35:20 | ERROR    | logging:callHandlers:1736 - Model training failed: No labeled exercise data found
2025-05-29 12:35:20 | ERROR    | logging:callHandlers:1736 - Background training failed: No labeled exercise data found
2025-05-29 12:35:54 | ERROR    | logging:callHandlers:1736 - No active model found with name: default_classifier
2025-05-29 12:36:07 | ERROR    | logging:callHandlers:1736 - Model training failed: No labeled exercise data found
2025-05-29 12:36:07 | ERROR    | logging:callHandlers:1736 - Background training failed: No labeled exercise data found
2025-05-29 12:36:08 | ERROR    | logging:callHandlers:1736 - No active model found with name: default_classifier
2025-05-29 12:36:21 | ERROR    | logging:callHandlers:1736 - No active model found with name: default_classifier
2025-05-29 12:36:40 | ERROR    | logging:callHandlers:1736 - Model training failed: No labeled exercise data found
2025-05-29 12:36:40 | ERROR    | logging:callHandlers:1736 - Background training failed: No labeled exercise data found
2025-05-29 12:36:41 | ERROR    | logging:callHandlers:1736 - No active model found with name: default_classifier
2025-05-29 12:43:11 | ERROR    | logging:callHandlers:1736 - No active model found with name: default_classifier
2025-06-04 13:31:11 | ERROR    | logging:callHandlers:1736 - No active model found with name: default_classifier
2025-06-04 13:54:32 | ERROR    | logging:callHandlers:1736 - No active model found with name: default_classifier
2025-06-05 17:14:41 | ERROR    | logging:callHandlers:1736 - No active model found with name: default_classifier
2025-06-05 17:14:58 | ERROR    | logging:callHandlers:1736 - No active model found with name: default_classifier
2025-06-05 17:15:03 | ERROR    | logging:callHandlers:1736 - No active model found with name: default_classifier
2025-06-05 17:15:06 | ERROR    | logging:callHandlers:1736 - No active model found with name: default_classifier
2025-06-05 17:32:21 | ERROR    | logging:callHandlers:1736 - No active model found with name: default_classifier
2025-06-05 17:38:11 | ERROR    | logging:callHandlers:1736 - No active model found with name: default_classifier
2025-06-05 17:38:51 | ERROR    | logging:callHandlers:1736 - No active model found with name: default_classifier
2025-06-05 17:39:00 | ERROR    | logging:callHandlers:1736 - No active model found with name: default_classifier
2025-06-05 17:43:17 | ERROR    | logging:callHandlers:1736 - No active model found with name: default_classifier
2025-06-05 17:47:04 | ERROR    | logging:callHandlers:1736 - No active model found with name: default_classifier
2025-06-05 17:47:17 | ERROR    | logging:callHandlers:1736 - No active model found with name: default_classifier
2025-06-05 17:47:30 | ERROR    | logging:callHandlers:1736 - No active model found with name: default_classifier
2025-06-05 17:47:45 | ERROR    | logging:callHandlers:1736 - No active model found with name: default_classifier
2025-06-05 17:51:08 | ERROR    | logging:callHandlers:1736 - Exception in ASGI application

Traceback (most recent call last):

  File "<string>", line 1, in <module>

  File "/usr/local/Cellar/python@3.13/3.13.3/Frameworks/Python.framework/Versions/3.13/lib/python3.13/multiprocessing/spawn.py", line 122, in spawn_main
    exitcode = _main(fd, parent_sentinel)
               │     │   └ 4
               │     └ 7
               └ <function _main at 0x10dd72200>

  File "/usr/local/Cellar/python@3.13/3.13.3/Frameworks/Python.framework/Versions/3.13/lib/python3.13/multiprocessing/spawn.py", line 135, in _main
    return self._bootstrap(parent_sentinel)
           │    │          └ 4
           │    └ <function BaseProcess._bootstrap at 0x10dbc3600>
           └ <SpawnProcess name='SpawnProcess-9' parent=27801 started>

  File "/usr/local/Cellar/python@3.13/3.13.3/Frameworks/Python.framework/Versions/3.13/lib/python3.13/multiprocessing/process.py", line 313, in _bootstrap
    self.run()
    │    └ <function BaseProcess.run at 0x10dbc2b60>
    └ <SpawnProcess name='SpawnProcess-9' parent=27801 started>

  File "/usr/local/Cellar/python@3.13/3.13.3/Frameworks/Python.framework/Versions/3.13/lib/python3.13/multiprocessing/process.py", line 108, in run
    self._target(*self._args, **self._kwargs)
    │    │        │    │        │    └ {'config': <uvicorn.config.Config object at 0x10f0eeba0>, 'target': <bound method Server.run of <uvicorn.server.Server object...
    │    │        │    │        └ <SpawnProcess name='SpawnProcess-9' parent=27801 started>
    │    │        │    └ ()
    │    │        └ <SpawnProcess name='SpawnProcess-9' parent=27801 started>
    │    └ <function subprocess_started at 0x10ea97240>
    └ <SpawnProcess name='SpawnProcess-9' parent=27801 started>

  File "/Users/kams/Documents/workspace/progo-app/Progo-BE/venv/lib/python3.13/site-packages/uvicorn/_subprocess.py", line 80, in subprocess_started
    target(sockets=sockets)
    │              └ [<socket.socket fd=3, family=2, type=1, proto=0, laddr=('0.0.0.0', 8001)>]
    └ <bound method Server.run of <uvicorn.server.Server object at 0x10f0eecf0>>
  File "/Users/kams/Documents/workspace/progo-app/Progo-BE/venv/lib/python3.13/site-packages/uvicorn/server.py", line 66, in run
    return asyncio.run(self.serve(sockets=sockets))
           │       │   │    │             └ [<socket.socket fd=3, family=2, type=1, proto=0, laddr=('0.0.0.0', 8001)>]
           │       │   │    └ <function Server.serve at 0x10ea95ee0>
           │       │   └ <uvicorn.server.Server object at 0x10f0eecf0>
           │       └ <function run at 0x10e73b380>
           └ <module 'asyncio' from '/usr/local/Cellar/python@3.13/3.13.3/Frameworks/Python.framework/Versions/3.13/lib/python3.13/asyncio...

  File "/usr/local/Cellar/python@3.13/3.13.3/Frameworks/Python.framework/Versions/3.13/lib/python3.13/asyncio/runners.py", line 195, in run
    return runner.run(main)
           │      │   └ <coroutine object Server.serve at 0x10f1ad7e0>
           │      └ <function Runner.run at 0x10e81ade0>
           └ <asyncio.runners.Runner object at 0x10f0ef770>

  File "/usr/local/Cellar/python@3.13/3.13.3/Frameworks/Python.framework/Versions/3.13/lib/python3.13/asyncio/runners.py", line 118, in run
    return self._loop.run_until_complete(task)
           │    │     │                  └ <Task pending name='Task-1' coro=<Server.serve() running at /Users/kams/Documents/workspace/progo-app/Progo-BE/venv/lib/pytho...
           │    │     └ <cyfunction Loop.run_until_complete at 0x10f2065a0>
           │    └ <uvloop.Loop running=True closed=False debug=False>
           └ <asyncio.runners.Runner object at 0x10f0ef770>

> File "/Users/kams/Documents/workspace/progo-app/Progo-BE/venv/lib/python3.13/site-packages/uvicorn/protocols/http/httptools_impl.py", line 409, in run_asgi
    result = await app(  # type: ignore[func-returns-value]
                   └ <uvicorn.middleware.proxy_headers.ProxyHeadersMiddleware object at 0x12cb26cf0>
  File "/Users/kams/Documents/workspace/progo-app/Progo-BE/venv/lib/python3.13/site-packages/uvicorn/middleware/proxy_headers.py", line 60, in __call__
    return await self.app(scope, receive, send)
                 │    │   │      │        └ <bound method RequestResponseCycle.send of <uvicorn.protocols.http.httptools_impl.RequestResponseCycle object at 0x12cd0c440>>
                 │    │   │      └ <bound method RequestResponseCycle.receive of <uvicorn.protocols.http.httptools_impl.RequestResponseCycle object at 0x12cd0c4...
                 │    │   └ {'type': 'http', 'asgi': {'version': '3.0', 'spec_version': '2.3'}, 'http_version': '1.1', 'server': ('127.0.0.1', 8001), 'cl...
                 │    └ <fastapi.applications.FastAPI object at 0x12cb263c0>
                 └ <uvicorn.middleware.proxy_headers.ProxyHeadersMiddleware object at 0x12cb26cf0>
  File "/Users/kams/Documents/workspace/progo-app/Progo-BE/venv/lib/python3.13/site-packages/fastapi/applications.py", line 1054, in __call__
    await super().__call__(scope, receive, send)
                           │      │        └ <bound method RequestResponseCycle.send of <uvicorn.protocols.http.httptools_impl.RequestResponseCycle object at 0x12cd0c440>>
                           │      └ <bound method RequestResponseCycle.receive of <uvicorn.protocols.http.httptools_impl.RequestResponseCycle object at 0x12cd0c4...
                           └ {'type': 'http', 'asgi': {'version': '3.0', 'spec_version': '2.3'}, 'http_version': '1.1', 'server': ('127.0.0.1', 8001), 'cl...
  File "/Users/kams/Documents/workspace/progo-app/Progo-BE/venv/lib/python3.13/site-packages/starlette/applications.py", line 112, in __call__
    await self.middleware_stack(scope, receive, send)
          │    │                │      │        └ <bound method RequestResponseCycle.send of <uvicorn.protocols.http.httptools_impl.RequestResponseCycle object at 0x12cd0c440>>
          │    │                │      └ <bound method RequestResponseCycle.receive of <uvicorn.protocols.http.httptools_impl.RequestResponseCycle object at 0x12cd0c4...
          │    │                └ {'type': 'http', 'asgi': {'version': '3.0', 'spec_version': '2.3'}, 'http_version': '1.1', 'server': ('127.0.0.1', 8001), 'cl...
          │    └ <starlette.middleware.errors.ServerErrorMiddleware object at 0x12cb27620>
          └ <fastapi.applications.FastAPI object at 0x12cb263c0>
  File "/Users/kams/Documents/workspace/progo-app/Progo-BE/venv/lib/python3.13/site-packages/starlette/middleware/errors.py", line 187, in __call__
    raise exc
  File "/Users/kams/Documents/workspace/progo-app/Progo-BE/venv/lib/python3.13/site-packages/starlette/middleware/errors.py", line 165, in __call__
    await self.app(scope, receive, _send)
          │    │   │      │        └ <function ServerErrorMiddleware.__call__.<locals>._send at 0x12cd140e0>
          │    │   │      └ <bound method RequestResponseCycle.receive of <uvicorn.protocols.http.httptools_impl.RequestResponseCycle object at 0x12cd0c4...
          │    │   └ {'type': 'http', 'asgi': {'version': '3.0', 'spec_version': '2.3'}, 'http_version': '1.1', 'server': ('127.0.0.1', 8001), 'cl...
          │    └ <starlette.middleware.cors.CORSMiddleware object at 0x12cb274d0>
          └ <starlette.middleware.errors.ServerErrorMiddleware object at 0x12cb27620>
  File "/Users/kams/Documents/workspace/progo-app/Progo-BE/venv/lib/python3.13/site-packages/starlette/middleware/cors.py", line 85, in __call__
    await self.app(scope, receive, send)
          │    │   │      │        └ <function ServerErrorMiddleware.__call__.<locals>._send at 0x12cd140e0>
          │    │   │      └ <bound method RequestResponseCycle.receive of <uvicorn.protocols.http.httptools_impl.RequestResponseCycle object at 0x12cd0c4...
          │    │   └ {'type': 'http', 'asgi': {'version': '3.0', 'spec_version': '2.3'}, 'http_version': '1.1', 'server': ('127.0.0.1', 8001), 'cl...
          │    └ <starlette.middleware.exceptions.ExceptionMiddleware object at 0x12cb27380>
          └ <starlette.middleware.cors.CORSMiddleware object at 0x12cb274d0>
  File "/Users/kams/Documents/workspace/progo-app/Progo-BE/venv/lib/python3.13/site-packages/starlette/middleware/exceptions.py", line 62, in __call__
    await wrap_app_handling_exceptions(self.app, conn)(scope, receive, send)
          │                            │    │    │     │      │        └ <function ServerErrorMiddleware.__call__.<locals>._send at 0x12cd140e0>
          │                            │    │    │     │      └ <bound method RequestResponseCycle.receive of <uvicorn.protocols.http.httptools_impl.RequestResponseCycle object at 0x12cd0c4...
          │                            │    │    │     └ {'type': 'http', 'asgi': {'version': '3.0', 'spec_version': '2.3'}, 'http_version': '1.1', 'server': ('127.0.0.1', 8001), 'cl...
          │                            │    │    └ <starlette.requests.Request object at 0x12cd0c6e0>
          │                            │    └ <fastapi.routing.APIRouter object at 0x12cb7ef10>
          │                            └ <starlette.middleware.exceptions.ExceptionMiddleware object at 0x12cb27380>
          └ <function wrap_app_handling_exceptions at 0x1102ba5c0>
  File "/Users/kams/Documents/workspace/progo-app/Progo-BE/venv/lib/python3.13/site-packages/starlette/_exception_handler.py", line 53, in wrapped_app
    raise exc
  File "/Users/kams/Documents/workspace/progo-app/Progo-BE/venv/lib/python3.13/site-packages/starlette/_exception_handler.py", line 42, in wrapped_app
    await app(scope, receive, sender)
          │   │      │        └ <function wrap_app_handling_exceptions.<locals>.wrapped_app.<locals>.sender at 0x12cd14220>
          │   │      └ <bound method RequestResponseCycle.receive of <uvicorn.protocols.http.httptools_impl.RequestResponseCycle object at 0x12cd0c4...
          │   └ {'type': 'http', 'asgi': {'version': '3.0', 'spec_version': '2.3'}, 'http_version': '1.1', 'server': ('127.0.0.1', 8001), 'cl...
          └ <fastapi.routing.APIRouter object at 0x12cb7ef10>
  File "/Users/kams/Documents/workspace/progo-app/Progo-BE/venv/lib/python3.13/site-packages/starlette/routing.py", line 714, in __call__
    await self.middleware_stack(scope, receive, send)
          │    │                │      │        └ <function wrap_app_handling_exceptions.<locals>.wrapped_app.<locals>.sender at 0x12cd14220>
          │    │                │      └ <bound method RequestResponseCycle.receive of <uvicorn.protocols.http.httptools_impl.RequestResponseCycle object at 0x12cd0c4...
          │    │                └ {'type': 'http', 'asgi': {'version': '3.0', 'spec_version': '2.3'}, 'http_version': '1.1', 'server': ('127.0.0.1', 8001), 'cl...
          │    └ <bound method Router.app of <fastapi.routing.APIRouter object at 0x12cb7ef10>>
          └ <fastapi.routing.APIRouter object at 0x12cb7ef10>
  File "/Users/kams/Documents/workspace/progo-app/Progo-BE/venv/lib/python3.13/site-packages/starlette/routing.py", line 734, in app
    await route.handle(scope, receive, send)
          │     │      │      │        └ <function wrap_app_handling_exceptions.<locals>.wrapped_app.<locals>.sender at 0x12cd14220>
          │     │      │      └ <bound method RequestResponseCycle.receive of <uvicorn.protocols.http.httptools_impl.RequestResponseCycle object at 0x12cd0c4...
          │     │      └ {'type': 'http', 'asgi': {'version': '3.0', 'spec_version': '2.3'}, 'http_version': '1.1', 'server': ('127.0.0.1', 8001), 'cl...
          │     └ <function Route.handle at 0x1102bbf60>
          └ APIRoute(path='/api/v1/workouts/', name='create_workout', methods=['POST'])
  File "/Users/kams/Documents/workspace/progo-app/Progo-BE/venv/lib/python3.13/site-packages/starlette/routing.py", line 288, in handle
    await self.app(scope, receive, send)
          │    │   │      │        └ <function wrap_app_handling_exceptions.<locals>.wrapped_app.<locals>.sender at 0x12cd14220>
          │    │   │      └ <bound method RequestResponseCycle.receive of <uvicorn.protocols.http.httptools_impl.RequestResponseCycle object at 0x12cd0c4...
          │    │   └ {'type': 'http', 'asgi': {'version': '3.0', 'spec_version': '2.3'}, 'http_version': '1.1', 'server': ('127.0.0.1', 8001), 'cl...
          │    └ <function request_response.<locals>.app at 0x12cbf77e0>
          └ APIRoute(path='/api/v1/workouts/', name='create_workout', methods=['POST'])
  File "/Users/kams/Documents/workspace/progo-app/Progo-BE/venv/lib/python3.13/site-packages/starlette/routing.py", line 76, in app
    await wrap_app_handling_exceptions(app, request)(scope, receive, send)
          │                            │    │        │      │        └ <function wrap_app_handling_exceptions.<locals>.wrapped_app.<locals>.sender at 0x12cd14220>
          │                            │    │        │      └ <bound method RequestResponseCycle.receive of <uvicorn.protocols.http.httptools_impl.RequestResponseCycle object at 0x12cd0c4...
          │                            │    │        └ {'type': 'http', 'asgi': {'version': '3.0', 'spec_version': '2.3'}, 'http_version': '1.1', 'server': ('127.0.0.1', 8001), 'cl...
          │                            │    └ <starlette.requests.Request object at 0x12cc81810>
          │                            └ <function request_response.<locals>.app.<locals>.app at 0x12cd142c0>
          └ <function wrap_app_handling_exceptions at 0x1102ba5c0>
  File "/Users/kams/Documents/workspace/progo-app/Progo-BE/venv/lib/python3.13/site-packages/starlette/_exception_handler.py", line 53, in wrapped_app
    raise exc
  File "/Users/kams/Documents/workspace/progo-app/Progo-BE/venv/lib/python3.13/site-packages/starlette/_exception_handler.py", line 42, in wrapped_app
    await app(scope, receive, sender)
          │   │      │        └ <function wrap_app_handling_exceptions.<locals>.wrapped_app.<locals>.sender at 0x12cd14400>
          │   │      └ <bound method RequestResponseCycle.receive of <uvicorn.protocols.http.httptools_impl.RequestResponseCycle object at 0x12cd0c4...
          │   └ {'type': 'http', 'asgi': {'version': '3.0', 'spec_version': '2.3'}, 'http_version': '1.1', 'server': ('127.0.0.1', 8001), 'cl...
          └ <function request_response.<locals>.app.<locals>.app at 0x12cd142c0>
  File "/Users/kams/Documents/workspace/progo-app/Progo-BE/venv/lib/python3.13/site-packages/starlette/routing.py", line 73, in app
    response = await f(request)
                     │ └ <starlette.requests.Request object at 0x12cc81810>
                     └ <function get_request_handler.<locals>.app at 0x12cbf7740>
  File "/Users/kams/Documents/workspace/progo-app/Progo-BE/venv/lib/python3.13/site-packages/fastapi/routing.py", line 327, in app
    content = await serialize_response(
                    └ <function serialize_response at 0x1102ba160>
  File "/Users/kams/Documents/workspace/progo-app/Progo-BE/venv/lib/python3.13/site-packages/fastapi/routing.py", line 176, in serialize_response
    raise ResponseValidationError(
          └ <class 'fastapi.exceptions.ResponseValidationError'>

fastapi.exceptions.ResponseValidationError: 6 validation errors:
  {'type': 'int_type', 'loc': ('response', 'id'), 'msg': 'Input should be a valid integer', 'input': None}
  {'type': 'missing', 'loc': ('response', 'start_time'), 'msg': 'Field required', 'input': <app.models.database.WorkoutSession object at 0x12cd0cec0>}
  {'type': 'missing', 'loc': ('response', 'end_time'), 'msg': 'Field required', 'input': <app.models.database.WorkoutSession object at 0x12cd0cec0>}
  {'type': 'missing', 'loc': ('response', 'target_reps'), 'msg': 'Field required', 'input': <app.models.database.WorkoutSession object at 0x12cd0cec0>}
  {'type': 'missing', 'loc': ('response', 'total_reps'), 'msg': 'Field required', 'input': <app.models.database.WorkoutSession object at 0x12cd0cec0>}
  {'type': 'missing', 'loc': ('response', 'total_sets'), 'msg': 'Field required', 'input': <app.models.database.WorkoutSession object at 0x12cd0cec0>}

2025-06-05 17:51:41 | ERROR    | logging:callHandlers:1736 - No active model found with name: default_classifier
2025-06-05 17:51:50 | ERROR    | logging:callHandlers:1736 - Exception in ASGI application

Traceback (most recent call last):

  File "<string>", line 1, in <module>

  File "/usr/local/Cellar/python@3.13/3.13.3/Frameworks/Python.framework/Versions/3.13/lib/python3.13/multiprocessing/spawn.py", line 122, in spawn_main
    exitcode = _main(fd, parent_sentinel)
               │     │   └ 4
               │     └ 7
               └ <function _main at 0x109bea200>

  File "/usr/local/Cellar/python@3.13/3.13.3/Frameworks/Python.framework/Versions/3.13/lib/python3.13/multiprocessing/spawn.py", line 135, in _main
    return self._bootstrap(parent_sentinel)
           │    │          └ 4
           │    └ <function BaseProcess._bootstrap at 0x109a3f600>
           └ <SpawnProcess name='SpawnProcess-10' parent=27801 started>

  File "/usr/local/Cellar/python@3.13/3.13.3/Frameworks/Python.framework/Versions/3.13/lib/python3.13/multiprocessing/process.py", line 313, in _bootstrap
    self.run()
    │    └ <function BaseProcess.run at 0x109a3eb60>
    └ <SpawnProcess name='SpawnProcess-10' parent=27801 started>

  File "/usr/local/Cellar/python@3.13/3.13.3/Frameworks/Python.framework/Versions/3.13/lib/python3.13/multiprocessing/process.py", line 108, in run
    self._target(*self._args, **self._kwargs)
    │    │        │    │        │    └ {'config': <uvicorn.config.Config object at 0x10af66ba0>, 'target': <bound method Server.run of <uvicorn.server.Server object...
    │    │        │    │        └ <SpawnProcess name='SpawnProcess-10' parent=27801 started>
    │    │        │    └ ()
    │    │        └ <SpawnProcess name='SpawnProcess-10' parent=27801 started>
    │    └ <function subprocess_started at 0x10a90b240>
    └ <SpawnProcess name='SpawnProcess-10' parent=27801 started>

  File "/Users/kams/Documents/workspace/progo-app/Progo-BE/venv/lib/python3.13/site-packages/uvicorn/_subprocess.py", line 80, in subprocess_started
    target(sockets=sockets)
    │              └ [<socket.socket fd=3, family=2, type=1, proto=0, laddr=('0.0.0.0', 8001)>]
    └ <bound method Server.run of <uvicorn.server.Server object at 0x10af66cf0>>
  File "/Users/kams/Documents/workspace/progo-app/Progo-BE/venv/lib/python3.13/site-packages/uvicorn/server.py", line 66, in run
    return asyncio.run(self.serve(sockets=sockets))
           │       │   │    │             └ [<socket.socket fd=3, family=2, type=1, proto=0, laddr=('0.0.0.0', 8001)>]
           │       │   │    └ <function Server.serve at 0x10a909ee0>
           │       │   └ <uvicorn.server.Server object at 0x10af66cf0>
           │       └ <function run at 0x10a5af380>
           └ <module 'asyncio' from '/usr/local/Cellar/python@3.13/3.13.3/Frameworks/Python.framework/Versions/3.13/lib/python3.13/asyncio...

  File "/usr/local/Cellar/python@3.13/3.13.3/Frameworks/Python.framework/Versions/3.13/lib/python3.13/asyncio/runners.py", line 195, in run
    return runner.run(main)
           │      │   └ <coroutine object Server.serve at 0x10b0297e0>
           │      └ <function Runner.run at 0x10a68ede0>
           └ <asyncio.runners.Runner object at 0x10af67770>

  File "/usr/local/Cellar/python@3.13/3.13.3/Frameworks/Python.framework/Versions/3.13/lib/python3.13/asyncio/runners.py", line 118, in run
    return self._loop.run_until_complete(task)
           │    │     │                  └ <Task pending name='Task-1' coro=<Server.serve() running at /Users/kams/Documents/workspace/progo-app/Progo-BE/venv/lib/pytho...
           │    │     └ <cyfunction Loop.run_until_complete at 0x10b0825a0>
           │    └ <uvloop.Loop running=True closed=False debug=False>
           └ <asyncio.runners.Runner object at 0x10af67770>

> File "/Users/kams/Documents/workspace/progo-app/Progo-BE/venv/lib/python3.13/site-packages/uvicorn/protocols/http/httptools_impl.py", line 409, in run_asgi
    result = await app(  # type: ignore[func-returns-value]
                   └ <uvicorn.middleware.proxy_headers.ProxyHeadersMiddleware object at 0x1288b2cf0>
  File "/Users/kams/Documents/workspace/progo-app/Progo-BE/venv/lib/python3.13/site-packages/uvicorn/middleware/proxy_headers.py", line 60, in __call__
    return await self.app(scope, receive, send)
                 │    │   │      │        └ <bound method RequestResponseCycle.send of <uvicorn.protocols.http.httptools_impl.RequestResponseCycle object at 0x128bc0440>>
                 │    │   │      └ <bound method RequestResponseCycle.receive of <uvicorn.protocols.http.httptools_impl.RequestResponseCycle object at 0x128bc04...
                 │    │   └ {'type': 'http', 'asgi': {'version': '3.0', 'spec_version': '2.3'}, 'http_version': '1.1', 'server': ('127.0.0.1', 8001), 'cl...
                 │    └ <fastapi.applications.FastAPI object at 0x1288b23c0>
                 └ <uvicorn.middleware.proxy_headers.ProxyHeadersMiddleware object at 0x1288b2cf0>
  File "/Users/kams/Documents/workspace/progo-app/Progo-BE/venv/lib/python3.13/site-packages/fastapi/applications.py", line 1054, in __call__
    await super().__call__(scope, receive, send)
                           │      │        └ <bound method RequestResponseCycle.send of <uvicorn.protocols.http.httptools_impl.RequestResponseCycle object at 0x128bc0440>>
                           │      └ <bound method RequestResponseCycle.receive of <uvicorn.protocols.http.httptools_impl.RequestResponseCycle object at 0x128bc04...
                           └ {'type': 'http', 'asgi': {'version': '3.0', 'spec_version': '2.3'}, 'http_version': '1.1', 'server': ('127.0.0.1', 8001), 'cl...
  File "/Users/kams/Documents/workspace/progo-app/Progo-BE/venv/lib/python3.13/site-packages/starlette/applications.py", line 112, in __call__
    await self.middleware_stack(scope, receive, send)
          │    │                │      │        └ <bound method RequestResponseCycle.send of <uvicorn.protocols.http.httptools_impl.RequestResponseCycle object at 0x128bc0440>>
          │    │                │      └ <bound method RequestResponseCycle.receive of <uvicorn.protocols.http.httptools_impl.RequestResponseCycle object at 0x128bc04...
          │    │                └ {'type': 'http', 'asgi': {'version': '3.0', 'spec_version': '2.3'}, 'http_version': '1.1', 'server': ('127.0.0.1', 8001), 'cl...
          │    └ <starlette.middleware.errors.ServerErrorMiddleware object at 0x1288b3620>
          └ <fastapi.applications.FastAPI object at 0x1288b23c0>
  File "/Users/kams/Documents/workspace/progo-app/Progo-BE/venv/lib/python3.13/site-packages/starlette/middleware/errors.py", line 187, in __call__
    raise exc
  File "/Users/kams/Documents/workspace/progo-app/Progo-BE/venv/lib/python3.13/site-packages/starlette/middleware/errors.py", line 165, in __call__
    await self.app(scope, receive, _send)
          │    │   │      │        └ <function ServerErrorMiddleware.__call__.<locals>._send at 0x128ba7f60>
          │    │   │      └ <bound method RequestResponseCycle.receive of <uvicorn.protocols.http.httptools_impl.RequestResponseCycle object at 0x128bc04...
          │    │   └ {'type': 'http', 'asgi': {'version': '3.0', 'spec_version': '2.3'}, 'http_version': '1.1', 'server': ('127.0.0.1', 8001), 'cl...
          │    └ <starlette.middleware.cors.CORSMiddleware object at 0x1288b34d0>
          └ <starlette.middleware.errors.ServerErrorMiddleware object at 0x1288b3620>
  File "/Users/kams/Documents/workspace/progo-app/Progo-BE/venv/lib/python3.13/site-packages/starlette/middleware/cors.py", line 85, in __call__
    await self.app(scope, receive, send)
          │    │   │      │        └ <function ServerErrorMiddleware.__call__.<locals>._send at 0x128ba7f60>
          │    │   │      └ <bound method RequestResponseCycle.receive of <uvicorn.protocols.http.httptools_impl.RequestResponseCycle object at 0x128bc04...
          │    │   └ {'type': 'http', 'asgi': {'version': '3.0', 'spec_version': '2.3'}, 'http_version': '1.1', 'server': ('127.0.0.1', 8001), 'cl...
          │    └ <starlette.middleware.exceptions.ExceptionMiddleware object at 0x1288b3380>
          └ <starlette.middleware.cors.CORSMiddleware object at 0x1288b34d0>
  File "/Users/kams/Documents/workspace/progo-app/Progo-BE/venv/lib/python3.13/site-packages/starlette/middleware/exceptions.py", line 62, in __call__
    await wrap_app_handling_exceptions(self.app, conn)(scope, receive, send)
          │                            │    │    │     │      │        └ <function ServerErrorMiddleware.__call__.<locals>._send at 0x128ba7f60>
          │                            │    │    │     │      └ <bound method RequestResponseCycle.receive of <uvicorn.protocols.http.httptools_impl.RequestResponseCycle object at 0x128bc04...
          │                            │    │    │     └ {'type': 'http', 'asgi': {'version': '3.0', 'spec_version': '2.3'}, 'http_version': '1.1', 'server': ('127.0.0.1', 8001), 'cl...
          │                            │    │    └ <starlette.requests.Request object at 0x128bc06e0>
          │                            │    └ <fastapi.routing.APIRouter object at 0x128a3ef10>
          │                            └ <starlette.middleware.exceptions.ExceptionMiddleware object at 0x1288b3380>
          └ <function wrap_app_handling_exceptions at 0x10c14a5c0>
  File "/Users/kams/Documents/workspace/progo-app/Progo-BE/venv/lib/python3.13/site-packages/starlette/_exception_handler.py", line 53, in wrapped_app
    raise exc
  File "/Users/kams/Documents/workspace/progo-app/Progo-BE/venv/lib/python3.13/site-packages/starlette/_exception_handler.py", line 42, in wrapped_app
    await app(scope, receive, sender)
          │   │      │        └ <function wrap_app_handling_exceptions.<locals>.wrapped_app.<locals>.sender at 0x128bc4180>
          │   │      └ <bound method RequestResponseCycle.receive of <uvicorn.protocols.http.httptools_impl.RequestResponseCycle object at 0x128bc04...
          │   └ {'type': 'http', 'asgi': {'version': '3.0', 'spec_version': '2.3'}, 'http_version': '1.1', 'server': ('127.0.0.1', 8001), 'cl...
          └ <fastapi.routing.APIRouter object at 0x128a3ef10>
  File "/Users/kams/Documents/workspace/progo-app/Progo-BE/venv/lib/python3.13/site-packages/starlette/routing.py", line 714, in __call__
    await self.middleware_stack(scope, receive, send)
          │    │                │      │        └ <function wrap_app_handling_exceptions.<locals>.wrapped_app.<locals>.sender at 0x128bc4180>
          │    │                │      └ <bound method RequestResponseCycle.receive of <uvicorn.protocols.http.httptools_impl.RequestResponseCycle object at 0x128bc04...
          │    │                └ {'type': 'http', 'asgi': {'version': '3.0', 'spec_version': '2.3'}, 'http_version': '1.1', 'server': ('127.0.0.1', 8001), 'cl...
          │    └ <bound method Router.app of <fastapi.routing.APIRouter object at 0x128a3ef10>>
          └ <fastapi.routing.APIRouter object at 0x128a3ef10>
  File "/Users/kams/Documents/workspace/progo-app/Progo-BE/venv/lib/python3.13/site-packages/starlette/routing.py", line 734, in app
    await route.handle(scope, receive, send)
          │     │      │      │        └ <function wrap_app_handling_exceptions.<locals>.wrapped_app.<locals>.sender at 0x128bc4180>
          │     │      │      └ <bound method RequestResponseCycle.receive of <uvicorn.protocols.http.httptools_impl.RequestResponseCycle object at 0x128bc04...
          │     │      └ {'type': 'http', 'asgi': {'version': '3.0', 'spec_version': '2.3'}, 'http_version': '1.1', 'server': ('127.0.0.1', 8001), 'cl...
          │     └ <function Route.handle at 0x10c14bf60>
          └ APIRoute(path='/api/v1/workouts/', name='create_workout', methods=['POST'])
  File "/Users/kams/Documents/workspace/progo-app/Progo-BE/venv/lib/python3.13/site-packages/starlette/routing.py", line 288, in handle
    await self.app(scope, receive, send)
          │    │   │      │        └ <function wrap_app_handling_exceptions.<locals>.wrapped_app.<locals>.sender at 0x128bc4180>
          │    │   │      └ <bound method RequestResponseCycle.receive of <uvicorn.protocols.http.httptools_impl.RequestResponseCycle object at 0x128bc04...
          │    │   └ {'type': 'http', 'asgi': {'version': '3.0', 'spec_version': '2.3'}, 'http_version': '1.1', 'server': ('127.0.0.1', 8001), 'cl...
          │    └ <function request_response.<locals>.app at 0x128ab76a0>
          └ APIRoute(path='/api/v1/workouts/', name='create_workout', methods=['POST'])
  File "/Users/kams/Documents/workspace/progo-app/Progo-BE/venv/lib/python3.13/site-packages/starlette/routing.py", line 76, in app
    await wrap_app_handling_exceptions(app, request)(scope, receive, send)
          │                            │    │        │      │        └ <function wrap_app_handling_exceptions.<locals>.wrapped_app.<locals>.sender at 0x128bc4180>
          │                            │    │        │      └ <bound method RequestResponseCycle.receive of <uvicorn.protocols.http.httptools_impl.RequestResponseCycle object at 0x128bc04...
          │                            │    │        └ {'type': 'http', 'asgi': {'version': '3.0', 'spec_version': '2.3'}, 'http_version': '1.1', 'server': ('127.0.0.1', 8001), 'cl...
          │                            │    └ <starlette.requests.Request object at 0x128b3d6d0>
          │                            └ <function request_response.<locals>.app.<locals>.app at 0x128bc4040>
          └ <function wrap_app_handling_exceptions at 0x10c14a5c0>
  File "/Users/kams/Documents/workspace/progo-app/Progo-BE/venv/lib/python3.13/site-packages/starlette/_exception_handler.py", line 53, in wrapped_app
    raise exc
  File "/Users/kams/Documents/workspace/progo-app/Progo-BE/venv/lib/python3.13/site-packages/starlette/_exception_handler.py", line 42, in wrapped_app
    await app(scope, receive, sender)
          │   │      │        └ <function wrap_app_handling_exceptions.<locals>.wrapped_app.<locals>.sender at 0x128bc42c0>
          │   │      └ <bound method RequestResponseCycle.receive of <uvicorn.protocols.http.httptools_impl.RequestResponseCycle object at 0x128bc04...
          │   └ {'type': 'http', 'asgi': {'version': '3.0', 'spec_version': '2.3'}, 'http_version': '1.1', 'server': ('127.0.0.1', 8001), 'cl...
          └ <function request_response.<locals>.app.<locals>.app at 0x128bc4040>
  File "/Users/kams/Documents/workspace/progo-app/Progo-BE/venv/lib/python3.13/site-packages/starlette/routing.py", line 73, in app
    response = await f(request)
                     │ └ <starlette.requests.Request object at 0x128b3d6d0>
                     └ <function get_request_handler.<locals>.app at 0x128ab7600>
  File "/Users/kams/Documents/workspace/progo-app/Progo-BE/venv/lib/python3.13/site-packages/fastapi/routing.py", line 327, in app
    content = await serialize_response(
                    └ <function serialize_response at 0x10c14a160>
  File "/Users/kams/Documents/workspace/progo-app/Progo-BE/venv/lib/python3.13/site-packages/fastapi/routing.py", line 176, in serialize_response
    raise ResponseValidationError(
          └ <class 'fastapi.exceptions.ResponseValidationError'>

fastapi.exceptions.ResponseValidationError: 2 validation errors:
  {'type': 'int_type', 'loc': ('response', 'id'), 'msg': 'Input should be a valid integer', 'input': None}
  {'type': 'datetime_type', 'loc': ('response', 'started_at'), 'msg': 'Input should be a valid datetime', 'input': None}

2025-06-05 17:52:48 | ERROR    | logging:callHandlers:1736 - No active model found with name: default_classifier
2025-06-05 17:52:55 | ERROR    | logging:callHandlers:1736 - Exception in ASGI application

Traceback (most recent call last):

  File "<string>", line 1, in <module>

  File "/usr/local/Cellar/python@3.13/3.13.3/Frameworks/Python.framework/Versions/3.13/lib/python3.13/multiprocessing/spawn.py", line 122, in spawn_main
    exitcode = _main(fd, parent_sentinel)
               │     │   └ 4
               │     └ 7
               └ <function _main at 0x10c2ee200>

  File "/usr/local/Cellar/python@3.13/3.13.3/Frameworks/Python.framework/Versions/3.13/lib/python3.13/multiprocessing/spawn.py", line 135, in _main
    return self._bootstrap(parent_sentinel)
           │    │          └ 4
           │    └ <function BaseProcess._bootstrap at 0x10c13f600>
           └ <SpawnProcess name='SpawnProcess-11' parent=27801 started>

  File "/usr/local/Cellar/python@3.13/3.13.3/Frameworks/Python.framework/Versions/3.13/lib/python3.13/multiprocessing/process.py", line 313, in _bootstrap
    self.run()
    │    └ <function BaseProcess.run at 0x10c13eb60>
    └ <SpawnProcess name='SpawnProcess-11' parent=27801 started>

  File "/usr/local/Cellar/python@3.13/3.13.3/Frameworks/Python.framework/Versions/3.13/lib/python3.13/multiprocessing/process.py", line 108, in run
    self._target(*self._args, **self._kwargs)
    │    │        │    │        │    └ {'config': <uvicorn.config.Config object at 0x10d65aba0>, 'target': <bound method Server.run of <uvicorn.server.Server object...
    │    │        │    │        └ <SpawnProcess name='SpawnProcess-11' parent=27801 started>
    │    │        │    └ ()
    │    │        └ <SpawnProcess name='SpawnProcess-11' parent=27801 started>
    │    └ <function subprocess_started at 0x10cfff240>
    └ <SpawnProcess name='SpawnProcess-11' parent=27801 started>

  File "/Users/kams/Documents/workspace/progo-app/Progo-BE/venv/lib/python3.13/site-packages/uvicorn/_subprocess.py", line 80, in subprocess_started
    target(sockets=sockets)
    │              └ [<socket.socket fd=3, family=2, type=1, proto=0, laddr=('0.0.0.0', 8001)>]
    └ <bound method Server.run of <uvicorn.server.Server object at 0x10d65acf0>>
  File "/Users/kams/Documents/workspace/progo-app/Progo-BE/venv/lib/python3.13/site-packages/uvicorn/server.py", line 66, in run
    return asyncio.run(self.serve(sockets=sockets))
           │       │   │    │             └ [<socket.socket fd=3, family=2, type=1, proto=0, laddr=('0.0.0.0', 8001)>]
           │       │   │    └ <function Server.serve at 0x10cffdee0>
           │       │   └ <uvicorn.server.Server object at 0x10d65acf0>
           │       └ <function run at 0x10ccaf380>
           └ <module 'asyncio' from '/usr/local/Cellar/python@3.13/3.13.3/Frameworks/Python.framework/Versions/3.13/lib/python3.13/asyncio...

  File "/usr/local/Cellar/python@3.13/3.13.3/Frameworks/Python.framework/Versions/3.13/lib/python3.13/asyncio/runners.py", line 195, in run
    return runner.run(main)
           │      │   └ <coroutine object Server.serve at 0x10d7197e0>
           │      └ <function Runner.run at 0x10cd8ade0>
           └ <asyncio.runners.Runner object at 0x10d65b770>

  File "/usr/local/Cellar/python@3.13/3.13.3/Frameworks/Python.framework/Versions/3.13/lib/python3.13/asyncio/runners.py", line 118, in run
    return self._loop.run_until_complete(task)
           │    │     │                  └ <Task pending name='Task-1' coro=<Server.serve() running at /Users/kams/Documents/workspace/progo-app/Progo-BE/venv/lib/pytho...
           │    │     └ <cyfunction Loop.run_until_complete at 0x10d7725a0>
           │    └ <uvloop.Loop running=True closed=False debug=False>
           └ <asyncio.runners.Runner object at 0x10d65b770>

> File "/Users/kams/Documents/workspace/progo-app/Progo-BE/venv/lib/python3.13/site-packages/uvicorn/protocols/http/httptools_impl.py", line 409, in run_asgi
    result = await app(  # type: ignore[func-returns-value]
                   └ <uvicorn.middleware.proxy_headers.ProxyHeadersMiddleware object at 0x12b0becf0>
  File "/Users/kams/Documents/workspace/progo-app/Progo-BE/venv/lib/python3.13/site-packages/uvicorn/middleware/proxy_headers.py", line 60, in __call__
    return await self.app(scope, receive, send)
                 │    │   │      │        └ <bound method RequestResponseCycle.send of <uvicorn.protocols.http.httptools_impl.RequestResponseCycle object at 0x12b2a0440>>
                 │    │   │      └ <bound method RequestResponseCycle.receive of <uvicorn.protocols.http.httptools_impl.RequestResponseCycle object at 0x12b2a04...
                 │    │   └ {'type': 'http', 'asgi': {'version': '3.0', 'spec_version': '2.3'}, 'http_version': '1.1', 'server': ('127.0.0.1', 8001), 'cl...
                 │    └ <fastapi.applications.FastAPI object at 0x12b0be3c0>
                 └ <uvicorn.middleware.proxy_headers.ProxyHeadersMiddleware object at 0x12b0becf0>
  File "/Users/kams/Documents/workspace/progo-app/Progo-BE/venv/lib/python3.13/site-packages/fastapi/applications.py", line 1054, in __call__
    await super().__call__(scope, receive, send)
                           │      │        └ <bound method RequestResponseCycle.send of <uvicorn.protocols.http.httptools_impl.RequestResponseCycle object at 0x12b2a0440>>
                           │      └ <bound method RequestResponseCycle.receive of <uvicorn.protocols.http.httptools_impl.RequestResponseCycle object at 0x12b2a04...
                           └ {'type': 'http', 'asgi': {'version': '3.0', 'spec_version': '2.3'}, 'http_version': '1.1', 'server': ('127.0.0.1', 8001), 'cl...
  File "/Users/kams/Documents/workspace/progo-app/Progo-BE/venv/lib/python3.13/site-packages/starlette/applications.py", line 112, in __call__
    await self.middleware_stack(scope, receive, send)
          │    │                │      │        └ <bound method RequestResponseCycle.send of <uvicorn.protocols.http.httptools_impl.RequestResponseCycle object at 0x12b2a0440>>
          │    │                │      └ <bound method RequestResponseCycle.receive of <uvicorn.protocols.http.httptools_impl.RequestResponseCycle object at 0x12b2a04...
          │    │                └ {'type': 'http', 'asgi': {'version': '3.0', 'spec_version': '2.3'}, 'http_version': '1.1', 'server': ('127.0.0.1', 8001), 'cl...
          │    └ <starlette.middleware.errors.ServerErrorMiddleware object at 0x12b0bf620>
          └ <fastapi.applications.FastAPI object at 0x12b0be3c0>
  File "/Users/kams/Documents/workspace/progo-app/Progo-BE/venv/lib/python3.13/site-packages/starlette/middleware/errors.py", line 187, in __call__
    raise exc
  File "/Users/kams/Documents/workspace/progo-app/Progo-BE/venv/lib/python3.13/site-packages/starlette/middleware/errors.py", line 165, in __call__
    await self.app(scope, receive, _send)
          │    │   │      │        └ <function ServerErrorMiddleware.__call__.<locals>._send at 0x12b28bf60>
          │    │   │      └ <bound method RequestResponseCycle.receive of <uvicorn.protocols.http.httptools_impl.RequestResponseCycle object at 0x12b2a04...
          │    │   └ {'type': 'http', 'asgi': {'version': '3.0', 'spec_version': '2.3'}, 'http_version': '1.1', 'server': ('127.0.0.1', 8001), 'cl...
          │    └ <starlette.middleware.cors.CORSMiddleware object at 0x12b0bf4d0>
          └ <starlette.middleware.errors.ServerErrorMiddleware object at 0x12b0bf620>
  File "/Users/kams/Documents/workspace/progo-app/Progo-BE/venv/lib/python3.13/site-packages/starlette/middleware/cors.py", line 85, in __call__
    await self.app(scope, receive, send)
          │    │   │      │        └ <function ServerErrorMiddleware.__call__.<locals>._send at 0x12b28bf60>
          │    │   │      └ <bound method RequestResponseCycle.receive of <uvicorn.protocols.http.httptools_impl.RequestResponseCycle object at 0x12b2a04...
          │    │   └ {'type': 'http', 'asgi': {'version': '3.0', 'spec_version': '2.3'}, 'http_version': '1.1', 'server': ('127.0.0.1', 8001), 'cl...
          │    └ <starlette.middleware.exceptions.ExceptionMiddleware object at 0x12b0bf380>
          └ <starlette.middleware.cors.CORSMiddleware object at 0x12b0bf4d0>
  File "/Users/kams/Documents/workspace/progo-app/Progo-BE/venv/lib/python3.13/site-packages/starlette/middleware/exceptions.py", line 62, in __call__
    await wrap_app_handling_exceptions(self.app, conn)(scope, receive, send)
          │                            │    │    │     │      │        └ <function ServerErrorMiddleware.__call__.<locals>._send at 0x12b28bf60>
          │                            │    │    │     │      └ <bound method RequestResponseCycle.receive of <uvicorn.protocols.http.httptools_impl.RequestResponseCycle object at 0x12b2a04...
          │                            │    │    │     └ {'type': 'http', 'asgi': {'version': '3.0', 'spec_version': '2.3'}, 'http_version': '1.1', 'server': ('127.0.0.1', 8001), 'cl...
          │                            │    │    └ <starlette.requests.Request object at 0x12b2a06e0>
          │                            │    └ <fastapi.routing.APIRouter object at 0x12b11ef10>
          │                            └ <starlette.middleware.exceptions.ExceptionMiddleware object at 0x12b0bf380>
          └ <function wrap_app_handling_exceptions at 0x10e83e5c0>
  File "/Users/kams/Documents/workspace/progo-app/Progo-BE/venv/lib/python3.13/site-packages/starlette/_exception_handler.py", line 53, in wrapped_app
    raise exc
  File "/Users/kams/Documents/workspace/progo-app/Progo-BE/venv/lib/python3.13/site-packages/starlette/_exception_handler.py", line 42, in wrapped_app
    await app(scope, receive, sender)
          │   │      │        └ <function wrap_app_handling_exceptions.<locals>.wrapped_app.<locals>.sender at 0x12b2a4180>
          │   │      └ <bound method RequestResponseCycle.receive of <uvicorn.protocols.http.httptools_impl.RequestResponseCycle object at 0x12b2a04...
          │   └ {'type': 'http', 'asgi': {'version': '3.0', 'spec_version': '2.3'}, 'http_version': '1.1', 'server': ('127.0.0.1', 8001), 'cl...
          └ <fastapi.routing.APIRouter object at 0x12b11ef10>
  File "/Users/kams/Documents/workspace/progo-app/Progo-BE/venv/lib/python3.13/site-packages/starlette/routing.py", line 714, in __call__
    await self.middleware_stack(scope, receive, send)
          │    │                │      │        └ <function wrap_app_handling_exceptions.<locals>.wrapped_app.<locals>.sender at 0x12b2a4180>
          │    │                │      └ <bound method RequestResponseCycle.receive of <uvicorn.protocols.http.httptools_impl.RequestResponseCycle object at 0x12b2a04...
          │    │                └ {'type': 'http', 'asgi': {'version': '3.0', 'spec_version': '2.3'}, 'http_version': '1.1', 'server': ('127.0.0.1', 8001), 'cl...
          │    └ <bound method Router.app of <fastapi.routing.APIRouter object at 0x12b11ef10>>
          └ <fastapi.routing.APIRouter object at 0x12b11ef10>
  File "/Users/kams/Documents/workspace/progo-app/Progo-BE/venv/lib/python3.13/site-packages/starlette/routing.py", line 734, in app
    await route.handle(scope, receive, send)
          │     │      │      │        └ <function wrap_app_handling_exceptions.<locals>.wrapped_app.<locals>.sender at 0x12b2a4180>
          │     │      │      └ <bound method RequestResponseCycle.receive of <uvicorn.protocols.http.httptools_impl.RequestResponseCycle object at 0x12b2a04...
          │     │      └ {'type': 'http', 'asgi': {'version': '3.0', 'spec_version': '2.3'}, 'http_version': '1.1', 'server': ('127.0.0.1', 8001), 'cl...
          │     └ <function Route.handle at 0x10e83ff60>
          └ APIRoute(path='/api/v1/workouts/', name='create_workout', methods=['POST'])
  File "/Users/kams/Documents/workspace/progo-app/Progo-BE/venv/lib/python3.13/site-packages/starlette/routing.py", line 288, in handle
    await self.app(scope, receive, send)
          │    │   │      │        └ <function wrap_app_handling_exceptions.<locals>.wrapped_app.<locals>.sender at 0x12b2a4180>
          │    │   │      └ <bound method RequestResponseCycle.receive of <uvicorn.protocols.http.httptools_impl.RequestResponseCycle object at 0x12b2a04...
          │    │   └ {'type': 'http', 'asgi': {'version': '3.0', 'spec_version': '2.3'}, 'http_version': '1.1', 'server': ('127.0.0.1', 8001), 'cl...
          │    └ <function request_response.<locals>.app at 0x12b1976a0>
          └ APIRoute(path='/api/v1/workouts/', name='create_workout', methods=['POST'])
  File "/Users/kams/Documents/workspace/progo-app/Progo-BE/venv/lib/python3.13/site-packages/starlette/routing.py", line 76, in app
    await wrap_app_handling_exceptions(app, request)(scope, receive, send)
          │                            │    │        │      │        └ <function wrap_app_handling_exceptions.<locals>.wrapped_app.<locals>.sender at 0x12b2a4180>
          │                            │    │        │      └ <bound method RequestResponseCycle.receive of <uvicorn.protocols.http.httptools_impl.RequestResponseCycle object at 0x12b2a04...
          │                            │    │        └ {'type': 'http', 'asgi': {'version': '3.0', 'spec_version': '2.3'}, 'http_version': '1.1', 'server': ('127.0.0.1', 8001), 'cl...
          │                            │    └ <starlette.requests.Request object at 0x12b21d6d0>
          │                            └ <function request_response.<locals>.app.<locals>.app at 0x12b2a4040>
          └ <function wrap_app_handling_exceptions at 0x10e83e5c0>
  File "/Users/kams/Documents/workspace/progo-app/Progo-BE/venv/lib/python3.13/site-packages/starlette/_exception_handler.py", line 53, in wrapped_app
    raise exc
  File "/Users/kams/Documents/workspace/progo-app/Progo-BE/venv/lib/python3.13/site-packages/starlette/_exception_handler.py", line 42, in wrapped_app
    await app(scope, receive, sender)
          │   │      │        └ <function wrap_app_handling_exceptions.<locals>.wrapped_app.<locals>.sender at 0x12b2a42c0>
          │   │      └ <bound method RequestResponseCycle.receive of <uvicorn.protocols.http.httptools_impl.RequestResponseCycle object at 0x12b2a04...
          │   └ {'type': 'http', 'asgi': {'version': '3.0', 'spec_version': '2.3'}, 'http_version': '1.1', 'server': ('127.0.0.1', 8001), 'cl...
          └ <function request_response.<locals>.app.<locals>.app at 0x12b2a4040>
  File "/Users/kams/Documents/workspace/progo-app/Progo-BE/venv/lib/python3.13/site-packages/starlette/routing.py", line 73, in app
    response = await f(request)
                     │ └ <starlette.requests.Request object at 0x12b21d6d0>
                     └ <function get_request_handler.<locals>.app at 0x12b197600>
  File "/Users/kams/Documents/workspace/progo-app/Progo-BE/venv/lib/python3.13/site-packages/fastapi/routing.py", line 327, in app
    content = await serialize_response(
                    └ <function serialize_response at 0x10e83e160>
  File "/Users/kams/Documents/workspace/progo-app/Progo-BE/venv/lib/python3.13/site-packages/fastapi/routing.py", line 176, in serialize_response
    raise ResponseValidationError(
          └ <class 'fastapi.exceptions.ResponseValidationError'>

fastapi.exceptions.ResponseValidationError: 2 validation errors:
  {'type': 'int_type', 'loc': ('response', 'id'), 'msg': 'Input should be a valid integer', 'input': None}
  {'type': 'datetime_type', 'loc': ('response', 'started_at'), 'msg': 'Input should be a valid datetime', 'input': None}

2025-06-05 17:56:10 | ERROR    | logging:callHandlers:1736 - No active model found with name: default_classifier
2025-06-05 17:57:44 | ERROR    | logging:callHandlers:1736 - No active model found with name: default_classifier
2025-06-05 17:58:16 | ERROR    | logging:callHandlers:1736 - No active model found with name: default_classifier
2025-06-05 17:58:39 | ERROR    | logging:callHandlers:1736 - No active model found with name: default_classifier
2025-06-05 17:59:25 | ERROR    | logging:callHandlers:1736 - No active model found with name: default_classifier
2025-06-05 18:01:16 | ERROR    | logging:callHandlers:1736 - No active model found with name: default_classifier
2025-06-05 18:01:16 | ERROR    | logging:callHandlers:1736 - No active model found with name: default_classifier
2025-06-05 18:01:20 | ERROR    | logging:callHandlers:1736 - No active model found with name: default_classifier
2025-06-05 18:01:20 | ERROR    | logging:callHandlers:1736 - No active model found with name: default_classifier
2025-06-05 18:03:18 | ERROR    | logging:callHandlers:1736 - No active model found with name: default_classifier
2025-06-05 18:03:18 | ERROR    | logging:callHandlers:1736 - No active model found with name: default_classifier
2025-06-05 18:04:33 | ERROR    | logging:callHandlers:1736 - No active model found with name: default_classifier
